<robot name="kuka_kr6">
  <link name="world"/>
  <joint name="base_joint" type="fixed">
    <parent link="world"/>
    <child link="base_link"/>
  </joint>
  <link name="base_link" />

  <link name="link1" />
  <joint name="joint1" type="revolute">
    <origin xyz="0 0 0.4" rpy="3.14159265 0 0" />
    <parent link="base_link" />
    <child link="link1" />
    <axis xyz="0 0 1" />
    <limit lower="-2.967059728" upper="2.967059728" effort="1" velocity="1"/>
  </joint>

  <link name="link2" />
  <joint name="joint2" type="revolute">
    <origin xyz="0.025 0 0" rpy="1.57079633 0 0" />
    <parent link="link1" />
    <child link="link2" />
    <axis xyz="0 0 1" />
    <limit lower="-3.316125579" upper="0.785398163" effort="1" velocity="1"/>
  </joint>

  <link name="link3" />
  <joint name="joint3" type="revolute">
    <origin xyz="0.315 0 0" rpy="0 0 0" />
    <parent link="link2" />
    <child link="link3" />
    <axis xyz="0 0 1" />
    <limit lower="-2.094395102" upper="2.722713633" effort="1" velocity="1"/>
  </joint>

  <link name="link4" />
  <joint name="joint4" type="revolute">
    <origin xyz="0.365 -0.035 0" rpy="0 -1.57079633 0" />
    <parent link="link3" />
    <child link="link4" />
    <axis xyz="0 0 1" />
    <limit lower="-3.228859116" upper="3.228859116" effort="1" velocity="1"/>
  </joint>

  <link name="link5" />
  <joint name="joint5" type="revolute">
    <origin xyz="0 0 0" rpy="0 1.57079633 0" />
    <parent link="link4" />
    <child link="link5" />
    <axis xyz="0 0 1" />
    <limit lower="-2.094395102" upper="2.094395102" effort="1" velocity="1"/>
  </joint>

  <link name="link6" />
  <joint name="joint6" type="revolute">
    <origin xyz="0 0 0" rpy="0 -1.57079633 0" />
    <parent link="link5" />
    <child link="link6" />
    <axis xyz="0 0 1" />
    <limit lower="-6.108652382" upper="6.108652382" effort="1" velocity="1"/>
  </joint>

  <link name="tip" />
  <joint name="tip_joint" type="fixed">
    <origin xyz="0 0 -0.08" rpy="3.14159265 0 1.57079633" />
    <parent link="link6" />
    <child link="tip" />
  </joint>
</robot>
