<?xml version="1.0" ?>
<!-- =================================================================================== -->
<!-- |    This document was autogenerated by xacro from src/kuka_kr6/robots/workcell.xacro | -->
<!-- |    EDITING THIS FILE BY HAND IS NOT RECOMMENDED                                 | -->
<!-- =================================================================================== -->
<robot name="workcell" xmlns:xacro="http://ros.org/wiki/xacro">
  <link name="world_frame"/>
  <!-- link list -->
  <link name="base_link">
    <visual>
      <origin rpy="0 0 0" xyz="0 0 0"/>
      <geometry>
        <mesh filename="package://kuka_kr6/robots/base_link.STL"/>
      </geometry>
      <material name="orange">
        <color rgba="1 0.43 0 1"/>
      </material>
    </visual>
    <collision>
      <geometry>
        <mesh filename="package://kuka_kr6/robots/base_link.STL"/>
      </geometry>
      <material name="yellow">
        <color rgba="0 1 1 1"/>
      </material>
    </collision>
  </link>
  <link name="link1">
    <visual>
      <origin rpy="0 0 0" xyz="0.025 0 0"/>
      <geometry>
        <mesh filename="package://kuka_kr6/robots/link1.STL"/>
      </geometry>
      <material name="orange"/>
    </visual>
    <collision>
      <geometry>
        <mesh filename="package://kuka_kr6/robots/link1.STL"/>
      </geometry>
      <material name="yellow"/>
    </collision>
  </link>
  <link name="link2">
    <visual>
      <origin rpy="0 0 0" xyz="0 0 0"/>
      <geometry>
        <mesh filename="package://kuka_kr6/robots/link2.STL"/>
      </geometry>
      <material name="orange"/>
    </visual>
    <collision>
      <geometry>
        <mesh filename="package://kuka_kr6/robots/link2.STL"/>
      </geometry>
      <material name="yellow"/>
    </collision>
  </link>
  <link name="link3">
    <visual>
      <origin rpy="0 0 0" xyz="0 -0.035 0"/>
      <geometry>
        <mesh filename="package://kuka_kr6/robots/link3.STL"/>
      </geometry>
      <material name="orange"/>
    </visual>
    <collision>
      <geometry>
        <mesh filename="package://kuka_kr6/robots/link3.STL"/>
      </geometry>
      <material name="yellow"/>
    </collision>
  </link>
  <link name="link4">
    <visual>
      <origin rpy="0 0 0" xyz="0 0 0"/>
      <geometry>
        <mesh filename="package://kuka_kr6/robots/link4.STL"/>
      </geometry>
      <material name="orange"/>
    </visual>
    <collision>
      <geometry>
        <mesh filename="package://kuka_kr6/robots/link4.STL"/>
      </geometry>
      <material name="yellow"/>
    </collision>
  </link>
  <link name="link5">
    <visual>
      <origin rpy="0 -1.57079633 0" xyz="0 0 0"/>
      <geometry>
        <mesh filename="package://kuka_kr6/robots/link5.STL"/>
      </geometry>
      <material name="orange"/>
    </visual>
    <collision>
      <geometry>
        <mesh filename="package://kuka_kr6/robots/link5.STL"/>
      </geometry>
      <material name="yellow"/>
    </collision>
  </link>
  <link name="link6">
    <visual>
      <origin rpy="0 0 0" xyz="0 0 0"/>
      <geometry>
        <mesh filename="package://kuka_kr6/robots/link6.STL"/>
      </geometry>
      <material name="orange"/>
    </visual>
    <collision>
      <geometry>
        <mesh filename="package://kuka_kr6/robots/link6.STL"/>
      </geometry>
      <material name="yellow"/>
    </collision>
  </link>
  <link name="tip"/>
  <!-- end of link list -->
  <!-- joint list -->
  <joint name="joint1" type="revolute">
    <origin rpy="3.14159265 0 0" xyz="0 0 0.4"/>
    <parent link="base_link"/>
    <child link="link1"/>
    <axis xyz="0 0 1"/>
    <limit effort="1" lower="-2.967059728" upper="2.967059728" velocity="1"/>
  </joint>
  <joint name="joint2" type="revolute">
    <origin rpy="1.57079633 0 0" xyz="0.025 0 0"/>
    <parent link="link1"/>
    <child link="link2"/>
    <axis xyz="0 0 1"/>
    <limit effort="1" lower="-3.316125579" upper="0.785398163" velocity="1"/>
  </joint>
  <joint name="joint3" type="revolute">
    <origin rpy="0 0 0" xyz="0.315 0 0"/>
    <parent link="link2"/>
    <child link="link3"/>
    <axis xyz="0 0 1"/>
    <limit effort="1" lower="-2.094395102" upper="2.722713633" velocity="1"/>
  </joint>
  <joint name="joint4" type="revolute">
    <origin rpy="0 -1.57079633 0" xyz="0.365 -0.035 0"/>
    <parent link="link3"/>
    <child link="link4"/>
    <axis xyz="0 0 1"/>
    <limit effort="1" lower="-3.228859116" upper="3.228859116" velocity="1"/>
  </joint>
  <joint name="joint5" type="revolute">
    <origin rpy="0 1.57079633 0" xyz="0 0 0"/>
    <parent link="link4"/>
    <child link="link5"/>
    <axis xyz="0 0 1"/>
    <limit effort="1" lower="-2.094395102" upper="2.094395102" velocity="1"/>
  </joint>
  <joint name="joint6" type="revolute">
    <origin rpy="0 -1.57079633 0" xyz="0 0 0"/>
    <parent link="link5"/>
    <child link="link6"/>
    <axis xyz="0 0 1"/>
    <limit effort="1" lower="-6.108652382" upper="6.108652382" velocity="1"/>
  </joint>
  <joint name="tip_joint" type="fixed">
    <origin rpy="3.14159265 0 1.57079633" xyz="0 0 -0.08"/>
    <parent link="link6"/>
    <child link="tip"/>
  </joint>
  <!-- end of joint list -->
  <!-- ROS base_link to World Coordinates transform -->
  <link name="base"/>
  <joint name="base_link-base" type="fixed">
    <origin rpy="0 0 0" xyz="0 0 0"/>
    <parent link="base_link"/>
    <child link="base"/>
  </joint>
  <link name="table_base"/>
  <link name="table_top">
    <visual>
      <geometry>
        <box size="0.5 0.5 0.05"/>
      </geometry>
      <origin rpy="0 0 0" xyz="0 0 0"/>
    </visual>
    <collision>
      <geometry>
        <box size="0.5 0.5 0.05"/>
      </geometry>
      <origin rpy="0 0 0" xyz="0 0 0"/>
    </collision>
  </link>
  <joint name="table_top" type="fixed">
    <parent link="table_base"/>
    <child link="table_top"/>
    <origin rpy="0 0 0" xyz="0 0 0.2"/>
  </joint>
  <link name="table_leg_1">
    <visual>
      <geometry>
        <box size="0.05 0.05 0.2"/>
      </geometry>
      <origin rpy="0 0 0" xyz="0 0 0"/>
    </visual>
    <collision>
      <geometry>
        <box size="0.05 0.05 0.2"/>
      </geometry>
      <origin rpy="0 0 0" xyz="0 0 0"/>
    </collision>
  </link>
  <joint name="table_leg_1" type="fixed">
    <parent link="table_base"/>
    <child link="table_leg_1"/>
    <origin rpy="0 0 0" xyz="-0.25 -0.25 0.1"/>
  </joint>
  <link name="table_leg_2">
    <visual>
      <geometry>
        <box size="0.05 0.05 0.2"/>
      </geometry>
      <origin rpy="0 0 0" xyz="0 0 0"/>
    </visual>
    <collision>
      <geometry>
        <box size="0.05 0.05 0.2"/>
      </geometry>
      <origin rpy="0 0 0" xyz="0 0 0"/>
    </collision>
  </link>
  <joint name="table_leg_2" type="fixed">
    <parent link="table_base"/>
    <child link="table_leg_2"/>
    <origin rpy="0 0 0" xyz="-0.25 0.25 0.1"/>
  </joint>
  <link name="table_leg_3">
    <visual>
      <geometry>
        <box size="0.05 0.05 0.2"/>
      </geometry>
      <origin rpy="0 0 0" xyz="0 0 0"/>
    </visual>
    <collision>
      <geometry>
        <box size="0.05 0.05 0.2"/>
      </geometry>
      <origin rpy="0 0 0" xyz="0 0 0"/>
    </collision>
  </link>
  <joint name="table_leg_3" type="fixed">
    <parent link="table_base"/>
    <child link="table_leg_3"/>
    <origin rpy="0 0 0" xyz="0.25 0.25 0.1"/>
  </joint>
  <link name="table_leg_4">
    <visual>
      <geometry>
        <box size="0.05 0.05 0.2"/>
      </geometry>
      <origin rpy="0 0 0" xyz="0 0 0"/>
    </visual>
    <collision>
      <geometry>
        <box size="0.05 0.05 0.2"/>
      </geometry>
      <origin rpy="0 0 0" xyz="0 0 0"/>
    </collision>
  </link>
  <joint name="table_leg_4" type="fixed">
    <parent link="table_base"/>
    <child link="table_leg_4"/>
    <origin rpy="0 0 0" xyz="0.25 -0.25 0.1"/>
  </joint>
  <joint name="world_to_robot" type="fixed">
    <parent link="world_frame"/>
    <child link="base_link"/>
    <origin rpy="0 0 0" xyz="0 0 0"/>
  </joint>
  <joint name="world_to_table" type="fixed">
    <parent link="world_frame"/>
    <child link="table_base"/>
    <origin rpy="0 0 0" xyz="0.5 0 0"/>
  </joint>
</robot>

